<?xml version="1.0"?>
<robot name="seven_dof_robot" xmlns:xacro="http://www.ros.org/wiki/xacro">

  <!-- Base Link -->
  <link name="base_link">
    <visual>
      <geometry>
        <cylinder length="0.1" radius="0.06"/>
      </geometry>
      <material name="blue">
        <color rgba="0 0 0.8 1"/>
      </material>
    </visual>
    <collision>
      <geometry>
        <cylinder length="0.1" radius="0.06"/>
      </geometry>
    </collision>
    <inertial>
      <mass value="1.0"/>
      <inertia ixx="0.01" ixy="0" ixz="0" iyy="0.01" iyz="0" izz="0.01"/>
    </inertial>
  </link>

  <!-- Joint 1 -->
  <link name="link1">
    <visual>
      <origin xyz="0 0 0" rpy="-1.5708 0 0" />
      <geometry>
        <cylinder length="0.12" radius="0.05"/>
      </geometry>
      <material name="red">
        <color rgba="0.8 0 0 1"/>
      </material>
    </visual>
    <collision>
      <geometry>
        <cylinder length="0.12" radius="0.05"/>
      </geometry>
    </collision>
    <inertial>
      <mass value="0.5"/>
      <inertia ixx="0.001" ixy="0" ixz="0" iyy="0.001" iyz="0" izz="0.001"/>
    </inertial>
  </link>

  <joint name="joint1" type="revolute">
    <parent link="base_link"/>
    <child link="link1"/>
    <origin xyz="0 0 0" rpy="0 0 0"/>
    <axis xyz="0 0 1"/>
    <limit lower="-2.61799388" upper="2.61799388" effort="10" velocity="2.0"/>
  </joint>

  <!-- Joint 2 -->
  <link name="link2">
    <visual>
      <origin xyz="0 -0.15 0" rpy="1.5708 0 0" />
      <geometry>
        <cylinder length="0.3" radius="0.05"/>
      </geometry>
      <material name="green">
        <color rgba="0 0.8 0 1"/>
      </material>
    </visual>
    <collision>
      <origin xyz="0 0 0.15" />
      <geometry>
        <cylinder length="0.3" radius="0.05"/>
      </geometry>
    </collision>
    <inertial>
      <mass value="0.5"/>
      <inertia ixx="0.001" ixy="0" ixz="0" iyy="0.001" iyz="0" izz="0.001"/>
    </inertial>
  </link>

  <joint name="joint2" type="revolute">
    <parent link="link1"/>
    <child link="link2"/>
    <origin xyz="0 0 0" rpy="-1.5708 0 0"/>
    <axis xyz="0 0 1"/>
    <limit lower="-1.57079633" upper="0.43633231" effort="10" velocity="2.0"/>
  </joint>

  <!-- Joint 3 -->
  <link name="link3">
    <visual>
      <origin xyz="0 0 0.300" rpy="-1.5708 0 0"/>
      <geometry>
        <cylinder length="0.1" radius="0.05"/>
      </geometry>
      <material name="yellow">
        <color rgba="0.8 0.8 0 1"/>
      </material>
    </visual>
    <collision>
      <geometry>
        <cylinder length="0.1" radius="0.05"/>
      </geometry>
    </collision>
    <inertial>
      <mass value="0.5"/>
      <inertia ixx="0.001" ixy="0" ixz="0" iyy="0.001" iyz="0" izz="0.001"/>
    </inertial>
  </link>

  <joint name="joint3" type="revolute">
    <parent link="link2"/>
    <child link="link3"/>
    <origin xyz="0 0 0" rpy="1.5708 0 0"/>
    <axis xyz="0 0 1"/>
    <limit lower="-2.61799388" upper="2.61799388" effort="10" velocity="2.0"/>
  </joint>

  <!-- Joint 4 -->
  <link name="link4">
    <visual>
      <origin xyz="0 -0.12235 0" rpy="1.5708 0 0" />
      <geometry>
        <cylinder length="0.2447" radius="0.05"/>
      </geometry>
      <material name="purple">
        <color rgba="0.8 0 0.8 1"/>
      </material>
    </visual>
    <collision>
      <origin xyz="0 0 0.12235" />
      <geometry>
        <cylinder length="0.2447" radius="0.05"/>
      </geometry>
    </collision>
    <inertial>
      <mass value="0.5"/>
      <inertia ixx="0.001" ixy="0" ixz="0" iyy="0.001" iyz="0" izz="0.001"/>
    </inertial>
  </link>

  <joint name="joint4" type="revolute">
    <parent link="link3"/>
    <child link="link4"/>
    <origin xyz="0 0 0.300" rpy="-1.5708 0 0"/>
    <axis xyz="0 0 1"/>
    <limit lower="-1.79768913" upper="0.43633231" effort="10" velocity="2.0"/>
  </joint>

  <!-- Joint 5 -->
  <link name="link5">
    <visual>
      <origin xyz="0 0 0.2447" rpy="-1.5708 0 0"/>
      <geometry>
        <cylinder length="0.1" radius="0.05"/>
      </geometry>
      <material name="orange">
        <color rgba="1.0 0.5 0 1"/>
      </material>
    </visual>
    <collision>
      <geometry>
        <cylinder length="0.1" radius="0.05"/>
      </geometry>
    </collision>
    <inertial>
      <mass value="0.5"/>
      <inertia ixx="0.001" ixy="0" ixz="0" iyy="0.001" iyz="0" izz="0.001"/>
    </inertial>
  </link>

  <joint name="joint5" type="revolute">
    <parent link="link4"/>
    <child link="link5"/>
    <origin xyz="0 0 0" rpy="1.5708 0 0"/>
    <axis xyz="0 0 1"/>
    <limit lower="-2.87979327" upper="2.87979327" effort="10" velocity="2.0"/>
  </joint>

  <!-- Joint 6 -->
  <link name="link6">
    <visual>
      <origin xyz="0 -0.0734 0" rpy="1.5708 0 0" />
      <geometry>
        <cylinder length="0.1468" radius="0.05"/>
      </geometry>
      <material name="cyan">
        <color rgba="0 0.8 0.8 1"/>
      </material>
    </visual>
    <collision>
      <origin xyz="0 0 0.0734" />
      <geometry>
        <cylinder length="0.1468" radius="0.05"/>
      </geometry>
    </collision>
    <inertial>
      <mass value="0.5"/>
      <inertia ixx="0.001" ixy="0" ixz="0" iyy="0.001" iyz="0" izz="0.001"/>
    </inertial>
  </link>

  <joint name="joint6" type="revolute">
    <parent link="link5"/>
    <child link="link6"/>
    <origin xyz="0 0 0.2447" rpy="-1.5708 0 0"/>
    <axis xyz="0 0 1"/>
    <limit lower="-1.53588974" upper="0.43633231" effort="10" velocity="2.0"/>
  </joint>

  <!-- Joint 7 -->
  <link name="link7">
    <visual>
      <origin xyz="0 0 0.1468" rpy="0 0 0"/>
      <geometry>
        <cylinder length="0.01" radius="0.05"/>
      </geometry>
      <material name="gray">
        <color rgba="0.5 0.5 0.5 1"/>
      </material>
    </visual>
    <collision>
      <geometry>
        <cylinder length="0.01" radius="0.05"/>
      </geometry>
    </collision>
    <inertial>
      <mass value="0.3"/>
      <inertia ixx="0.0005" ixy="0" ixz="0" iyy="0.0005" iyz="0" izz="0.0005"/>
    </inertial>
  </link>

  <joint name="joint7" type="revolute">
    <parent link="link6"/>
    <child link="link7"/>
    <origin xyz="0 0 0" rpy="1.5708 0 0"/>
    <axis xyz="0 0 1"/>
    <limit lower="-2.96705973" upper="2.96705973" effort="10" velocity="2.0"/>
  </joint>

  <!-- End Effector Frame -->
  <link name="end_effector">
    <visual>
      <geometry>
        <box size="0.01 0.01 0.01"/>
      </geometry>
      <material name="red">
        <color rgba="1 0 0 0.5"/>
      </material>
    </visual>
    <collision>
      <geometry>
        <box size="0.01 0.01 0.01"/>
      </geometry>
    </collision>
    <inertial>
      <mass value="0.1"/>
      <inertia ixx="0.0001" ixy="0" ixz="0" iyy="0.0001" iyz="0" izz="0.0001"/>
    </inertial>
  </link>

  <joint name="end_effector_joint" type="fixed">
    <parent link="link7"/>
    <child link="end_effector"/>
    <origin xyz="0 0 0.1468" rpy="0 0 0"/>
  </joint>

</robot>